Workbook

Sheet Guide
A1: Guide | B1: Explanation of all sheets
A3: Red sheet | B3: API to the spatial model
A4: Q | B4: Quantities from the spatial model
A6: 1 | B6: City-scale financial models
A7: 1off-site | B7: Off-site costs and revenues, e.g. for trunk infrastructure (costs) and value capture along the trunk line (revenue).
A8: 1site | B8: Optional calculations on landowners and their lands: e.g. for structuring a potential land pooling and land readjustment (LPLR) project
A9: 1db | B9: City Scale Proforma (DashBoard representation)
A11: 2 | B11: Neighborhood-scale financial models
A12: 2neighborhood | B12: Neighborhood scale financial model
A13: 2db | B13: Neighborhood Scale Proforma (DashBoard representation)
A15: 3 | B15: Cluster-scale financial models
A16: 3cluster_artery | B16: Financial model for off-grid clusters along ARTeries
A17: 3cluster_secondary | B17: Financial model for off-grid clusters along SECondaries
A18: 3cluster_local | B18: Financial model for off-grid clusters along local roads that a SINGLE level of clusters
A19: 3cluster_2levels | B19: Financial model for off-grid clusters along local roads that a MULTIPLE level of clusters
A20: 3db | B20: Cluster Scale Proforma (DashBoard representation)
A22: 4 | B22: Building-scale financial models
A23: 4buildings | B23: Building scale financial model
A24: 4db | B24: Building Scale Proforma (DashBoard representation)
A26: 5 | B26: Unit-scale financial models
A27: 5dwellings | B27: Carving out main residential units as well as optional rooms for sublet from the residential area
A28: 5finande | B28: housing finance model, including rental revenue from sublets
A29: 5affordability | B29: Affordability assessment: which households are able to afford main dwellings for ownership and sublet rental rooms?
A30: 5db | B30: Dwelling Scale Proforma (DashBoard representation)
A32: 6 | B32: Demographic projections
A33: 6demographics | B33: Demographic projections, assuming intital and consolidated lot development, number of dwelling units, and household size
A34: 6db | B34: Demographic projection summary
A36: blue sheets | B36: Negotiation and mediation, phasing, and financial efficiency
A37: stakes | B37: allocation of costs and benefits across stakeholders
... A43: Legal information | B43: This spreadsheet is IP of Mat Nohn alias Rapid Urbanism. Contact: nohn@rapidurbanism.com

Sheet Q
A1: Public street network (length)
A2: Public network, by network level (in color code) | C2: 2-sided @100% | D2: 1-sided @50% | E2: zero sided (@tbd) | F2: Subtotal project-borne
B3: Arteries (main roads) | C3: 0 | D3: 0 | E3: 0 | F3: =C3+D3/2 -> 0
B4: Secondaries (distributor roads) | C4: 0 | D4: 0 | E4: 0 | F4: =C4+D4/2 -> 0
B5: Tertiaries (access and local roads) | C5: 0 | D5: 0 | E5: 0 | F5: =C5+D5/2 -> 0
B6: Subtotal project-borne | C6: =SUM(C3:C5) -> 0 | D6: =SUM(D3:D5)/2 -> 0 | E6: =SUM(E3:E5)*0 -> 0 | F6: =SUM(F3:F5) -> 0
A8: Land use (city and neighborhood scale) | X8: Lots and buildings (idealized)
A9: Land uses, by location (in color code) | C9: Environmental reservation | D9: Social reservation | E9: Other non-developable area | F9: Non-developable area | G9: Public streets | H9: City-scale public open spaces, subtotal | I9: City-scale public amenities, subtotal | J9: District-scale public open spaces, subtotal | K9: District-scale public amenities, subtotal | L9: Neighborhood-scale open spaces, subtotal | M9: Neighborhood-scale public amenities, subtotal | N9: Public lands, subtotal | O9: Private lands, subtotals | P9: Developable area, subtotals | Q9: All lands, totals | R9: Distribution (share of total) | X9: Number of lots | Y9: lot d | Z9: lot w | AA9: lot A | AB9: front margin | AC9: back margin | AD9: footprint d | AE9: side margin | AF9: side margin 2 | AG9: footprint w | AH9: footprint A | AI9: floors regular | AJ9: corner bonus | AK9: floors final | AL9: floor area | AM9: max. FAR viable | AO9: starter w | AP9: starter d | AQ9: starter f | AR9: starter w | AS9: starter d | AT9: starter f | AU9: Starter building, average floor area, if any
B10: =C9 -> Environmental reservation | C10: =C60*10000 -> 0 | F10: =SUM(C10:E10) -> 0 | Q10: =F10 -> 0 | R10: =Q10/Q37 -> #DIV/0!
B11: =D9 -> Social reservation | D11: =D60*10000 -> 0 | F11: =SUM(C11:E11) -> 0 | Q11: =F11 -> 0 | R11: =Q11/Q37 -> #DIV/0!
B12: =E9 -> Other non-developable area | E12: 0 | F12: =SUM(C12:E12) -> 0 | Q12: =F12 -> 0 | R12: =Q12/Q37 -> #DIV/0!
B13: Reservations, outside neighborhod | C13: =C10 -> 0 | D13: =D11 -> 0 | E13: =E12 -> 0 | F13: =SUM(F10:F12) -> 0 | Q13: =SUM(Q10:Q12) -> 0 | R13: =Q13/Q37 -> #DIV/0!
B14: Artery x artery (corner) | H14: 0 | I14: 0 | J14: 0 | K14: 0 | L14: 0 | M14: 0 | N14: =SUM(G14:M14) -> 0 | O14: 0 | P14: =SUM(N14:O14) -> 0 | Q14: =P14 -> 0 | R14: =Q14/Q37 -> #DIV/0! | U14: Artery x artery (corner) | X14: 0 | Y14: =Y17 -> 0 | Z14: =Y17 -> 0 | AA14: =Z14*Y14 -> 0 | AB14: =AB17 -> 0 | AC14: =AC17 -> 0 | AD14: =Y14-AB14-AC14 -> 0 | AE14: =AE17 -> 0 | AF14: =AE17 -> 0 | AG14: =Z14-AE14-AF14 -> 0 | AH14: =AG14*AD14 -> 0 | AJ14: 0 | AK14: =ROUND(AI17*(1+AJ14),0) -> 0 | AL14: =AG14*AD14*AK14 -> 0 | AM14: =IF(AA14=0,0,AL14/AA14) -> 0 | AO14: 0 | AP14: 0 | AQ14: 0 | AR14: =AO14*AG14 -> 0 | AS14: =AP14*AD14 -> 0 | AT14: =ROUND(AQ14*AK14,0) -> 0 | AU14: =AL14*AP14*AQ14 -> 0
B15: Artery x secondary (corner) | H15: 0 | I15: 0 | J15: 0 | K15: 0 | L15: 0 | M15: 0 | N15: =SUM(G15:M15) -> 0 | O15: 0 | P15: =SUM(N15:O15) -> 0 | Q15: =P15 -> 0 | R15: =Q15/Q37 -> #DIV/0! | U15: Artery x secondary (corner) | X15: 0 | Y15: =Y17 -> 0 | Z15: =Y21 -> 0 | AA15: =Z15*Y15 -> 0 | AB15: =AB17 -> 0 | AC15: =AC17 -> 0 | AD15: =Y15-AB15-AC15 -> 0 | AE15: =AE17 -> 0 | AF15: =AE21 -> 0 | AG15: =Z15-AE15-AF15 -> 0 | AH15: =AG15*AD15 -> 0 | AJ15: 0 | AK15: =ROUND(AI17*(1+AJ15),0) -> 0 | AL15: =AG15*AD15*AK15 -> 0 | AM15: =IF(AA15=0,0,AL15/AA15) -> 0 | AO15: 0 | AP15: 0 | AQ15: 0 | AR15: =AO15*AG15 -> 0 | AS15: =AP15*AD15 -> 0 | AT15: =ROUND(AQ15*AK15,0) -> 0 | AU15: =AL15*AP15*AQ15 -> 0
B16: Artery x tertiary (corner) | H16: 0 | I16: 0 | J16: 0 | K16: 0 | L16: 0 | M16: 0 | N16: =SUM(G16:M16) -> 0 | O16: 0 | P16: =SUM(N16:O16) -> 0 | Q16: =P16 -> 0 | R16: =Q16/Q37 -> #DIV/0! | U16: Artery x tertiary (corner) | X16: 0 | Y16: =Y17 -> 0 | Z16: =Y24 -> 0 | AA16: =Z16*Y16 -> 0 | AB16: =AB17 -> 0 | AC16: =AC17 -> 0 | AD16: =Y16-AB16-AC16 -> 0 | AE16: =AE17 -> 0 | AF16: =AE24 -> 0 | AG16: =Z16-AE16-AF16 -> 0 | AH16: =AG16*AD16 -> 0 | AJ16: 0 | AK16: =ROUND(AI17*(1+AJ16),0) -> 0 | AL16: =AG16*AD16*AK16 -> 0 | AM16: =IF(AA16=0,0,AL16/AA16) -> 0 | AO16: 0 | AP16: 0 | AQ16: 0 | AR16: =AO16*AG16 -> 0 | AS16: =AP16*AD16 -> 0 | AT16: =ROUND(AQ16*AK16,0) -> 0 | AU16: =AL16*AP16*AQ16 -> 0
B17: Artery (regular) | H17: 0 | I17: 0 | J17: 0 | K17: 0 | L17: 0 | M17: 0 | N17: =SUM(G17:M17) -> 0 | O17: 0 | P17: =SUM(N17:O17) -> 0 | Q17: =P17 -> 0 | R17: =Q17/Q37 -> #DIV/0! | U17: Artery (regular) | X17: 0 | Y17: 0 | Z17: 0 | AA17: =Z17*Y17 -> 0 | AB17: 0 | AC17: 0 | AD17: =Y17-AB17-AC17 -> 0 | AE17: 0 | AF17: =AE17 -> 0 | AG17: =Z17-AE17-AF17 -> 0 | AH17: =AG17*AD17 -> 0 | AI17: 0 | AJ17: 0 | AK17: =ROUND(AI17*(1+AJ17),0) -> 0 | AL17: =AG17*AD17*AK17 -> 0 | AM17: =IF(AA17=0,0,AL17/AA17) -> 0 | AO17: 0 | AP17: 0 | AQ17: 0 | AR17: =AO17*AG17 -> 0 | AS17: =AP17*AD17 -> 0 | AT17: =ROUND(AQ17*AK17,0) -> 0 | AU17: =AL17*AP17*AQ17 -> 0
A18: Land on arteries, subtotal | F18: =SUM(F14:F17) -> 0 | H18: =SUM(H14:H17) -> 0 | I18: =SUM(I14:I17) -> 0 | J18: =SUM(J14:J17) -> 0 | K18: =SUM(K14:K17) -> 0 | L18: =SUM(L14:L17) -> 0 | M18: =SUM(M14:M17) -> 0 | N18: =SUM(N14:N17) -> 0 | O18: =SUM(O14:O17) -> 0 | ... Q18: =SUM(Q14:Q17) -> 0 | R18: =Q18/Q37 -> #DIV/0! | T18: w/path | X18: =C45*2 -> 0 | Y18: =Y17 -> 0 | Z18: =Z17 -> 0 | AA18: =AA17 -> 0 | AB18: =AB17 -> 0 | AC18: =AC17 -> 0 | AD18: =AD17 -> 0 | AE18: =AE17 -> 0 | AF18: =AF17 -> 0 | ... AH18: =AH17 -> 0 | AK18: =AK17 -> 0 | AL18: =AL17 -> 0 | AM18: =IF(AA18=0,0,AL18/AA18) -> 0 | AO18: =AO17 -> 0 | AP18: =AP17 -> 0 | AQ18: =AQ17 -> 0 | AR18: =AO18*AG18 -> 0 | AS18: =AP18*AD18 -> 0 | AT18: =ROUND(AQ18*AK18,0) -> 0 | AU18: =AU17 -> 0
B19: Secondary x secondary (corner) | H19: 0 | I19: 0 | J19: 0 | K19: 0 | L19: 0 | M19: 0 | N19: =SUM(G19:M19) -> 0 | O19: 0 | P19: =SUM(N19:O19) -> 0 | Q19: =P19 -> 0 | R19: =Q19/Q37 -> #DIV/0! | U19: Secondary x secondary (corner) | X19: 0 | Y19: =Y21 -> 0 | Z19: =Y21 -> 0 | AA19: =Z19*Y19 -> 0 | AB19: =AB21 -> 0 | AC19: =AC21 -> 0 | AD19: =Y19-AB19-AC19 -> 0 | AE19: =AE21 -> 0 | AF19: =AE21 -> 0 | AG19: =Z19-AE19-AF19 -> 0 | AH19: =AG19*AD19 -> 0 | AJ19: =AJ15 -> 0 | AK19: =ROUND(AI21*(1+AJ19),0) -> 0 | AL19: =AG19*AD19*AK19 -> 0 | AM19: =IF(AA19=0,0,AL19/AA19) -> 0 | AO19: 0 | AP19: 0 | AQ19: 0 | AR19: =AO19*AG19 -> 0 | AS19: =AP19*AD19 -> 0 | AT19: =ROUND(AQ19*AK19,0) -> 0 | AU19: =AL19*AP19*AQ19 -> 0
B20: Secondary x tertiary (corner) | H20: 0 | I20: 0 | J20: 0 | K20: 0 | L20: 0 | M20: 0 | N20: =SUM(G20:M20) -> 0 | O20: 0 | P20: =SUM(N20:O20) -> 0 | Q20: =P20 -> 0 | R20: =Q20/Q37 -> #DIV/0! | U20: Secondary x tertiary (corner) | X20: 0 | Y20: =Y21 -> 0 | Z20: =Y24 -> 0 | AA20: =Z20*Y20 -> 0 | AB20: =AB21 -> 0 | AC20: =AC21 -> 0 | AD20: =Y20-AB20-AC20 -> 0 | AE20: =AE21 -> 0 | AF20: =AE24 -> 0 | AG20: =Z20-AE20-AF20 -> 0 | AH20: =AG20*AD20 -> 0 | AJ20: =AJ16 -> 0 | AK20: =ROUND(AI21*(1+AJ20),0) -> 0 | AL20: =AG20*AD20*AK20 -> 0 | AM20: =IF(AA20=0,0,AL20/AA20) -> 0 | AO20: 0 | AP20: 0 | AQ20: 0 | AR20: =AO20*AG20 -> 0 | AS20: =AP20*AD20 -> 0 | AT20: =ROUND(AQ20*AK20,0) -> 0 | AU20: =AL20*AP20*AQ20 -> 0
B21: Secondary (regular) | H21: 0 | I21: 0 | J21: 0 | K21: 0 | L21: 0 | M21: 0 | N21: =SUM(G21:M21) -> 0 | O21: 0 | P21: =SUM(N21:O21) -> 0 | Q21: =P21 -> 0 | R21: =Q21/Q37 -> #DIV/0! | U21: Secondary (regular) | X21: 0 | Y21: 0 | Z21: 0 | AA21: =Z21*Y21 -> 0 | AB21: 0 | AC21: 0 | AD21: =Y21-AB21-AC21 -> 0 | AE21: 0 | AF21: =AE21 -> 0 | AG21: =Z21-AE21-AF21 -> 0 | AH21: =AG21*AD21 -> 0 | AI21: 0 | AJ21: 0 | AK21: =ROUND(AI21*(1+AJ21),0) -> 0 | AL21: =AG21*AD21*AK21 -> 0 | AM21: =IF(AA21=0,0,AL21/AA21) -> 0 | AO21: 0 | AP21: 0 | AQ21: 0 | AR21: =AO21*AG21 -> 0 | AS21: =AP21*AD21 -> 0 | AT21: =ROUND(AQ21*AK21,0) -> 0 | AU21: =AL21*AP21*AQ21 -> 0
B22: Land on secondaries, subtotal | F22: =SUM(F19:F21) -> 0 | H22: =SUM(H19:H21) -> 0 | I22: =SUM(I19:I21) -> 0 | J22: =SUM(J19:J21) -> 0 | K22: =SUM(K19:K21) -> 0 | L22: =SUM(L19:L21) -> 0 | M22: =SUM(M19:M21) -> 0 | N22: =SUM(N19:N21) -> 0 | O22: =SUM(O19:O21) -> 0 | ... Q22: =SUM(Q19:Q21) -> 0 | R22: =Q22/Q37 -> #DIV/0! | U22: w/ path | X22: =C46*2 -> 0 | Y22: =Y21 -> 0 | Z22: =Z21 -> 0 | AA22: =AA21 -> 0 | AB22: =AB21 -> 0 | AC22: =AC21 -> 0 | AD22: =AD21 -> 0 | AE22: =AE21 -> 0 | AF22: =AF21 -> 0 | ... AH22: =AH21 -> 0 | AK22: =AK21 -> 0 | AL22: =AL21 -> 0 | AM22: =IF(AA22=0,0,AL22/AA22) -> 0 | AO22: =AO21 -> 0 | AP22: =AP21 -> 0 | AQ22: =AQ21 -> 0 | AR22: =AO22*AG22 -> 0 | AS22: =AP22*AD22 -> 0 | AT22: =ROUND(AQ22*AK22,0) -> 0 | AU22: =AU21 -> 0
B23: Tertiary x tertiary (corner) | H23: 0 | I23: 0 | J23: 0 | K23: 0 | L23: 0 | M23: 0 | N23: =SUM(G23:M23) -> 0 | O23: 0 | P23: =SUM(N23:O23) -> 0 | Q23: =P23 -> 0 | R23: =Q23/Q37 -> #DIV/0! | U23: Tertiary x tertiary (corner) | X23: 0 | Y23: =Y24 -> 0 | Z23: =Y24 -> 0 | AA23: =Z23*Y23 -> 0 | AB23: =AB24 -> 0 | AC23: =AC24 -> 0 | AD23: =Y23-AB23-AC23 -> 0 | AE23: =AE24 -> 0 | AF23: =AE24 -> 0 | AG23: =Z23-AE23-AF23 -> 0 | AH23: =AG23*AD23 -> 0 | AJ23: =AJ16 -> 0 | AK23: =ROUND(AI24*(1+AJ23),0) -> 0 | AL23: =AG23*AD23*AK23 -> 0 | AM23: =IF(AA23=0,0,AL23/AA23) -> 0 | AO23: 0 | AP23: 0 | AQ23: 0 | AR23: =AO23*AG23 -> 0 | AS23: =AP23*AD23 -> 0 | AT23: =ROUND(AQ23*AK23,0) -> 0 | AU23: =AL23*AP23*AQ23 -> 0
B24: Tertiary (regular) | H24: 0 | I24: 0 | J24: 0 | K24: 0 | L24: 0 | M24: 0 | N24: =SUM(G24:M24) -> 0 | O24: 0 | P24: =SUM(N24:O24) -> 0 | Q24: =P24 -> 0 | R24: =Q24/Q37 -> #DIV/0! | U24: Tertiary (regular) | X24: 0 | Y24: 0 | Z24: 0 | AA24: =Z24*Y24 -> 0 | AB24: 0 | AC24: 0 | AD24: =Y24-AB24-AC24 -> 0 | AE24: 0 | AF24: =AE24 -> 0 | AG24: =Z24-AE24-AF24 -> 0 | AH24: =AG24*AD24 -> 0 | AI24: 0 | AJ24: 0 | AK24: =ROUND(AI24*(1+AJ24),0) -> 0 | AL24: =AG24*AD24*AK24 -> 0 | AM24: =IF(AA24=0,0,AL24/AA24) -> 0 | AO24: 0 | AP24: 0 | AQ24: 0 | AR24: =AO24*AG24 -> 0 | AS24: =AP24*AD24 -> 0 | AT24: =ROUND(AQ24*AK24,0) -> 0 | AU24: =AL24*AP24*AQ24 -> 0
B25: Land on local roads, subtotal | F25: =SUM(F23:F24) -> 0 | H25: =SUM(H23:H24) -> 0 | I25: =SUM(I23:I24) -> 0 | J25: =SUM(J23:J24) -> 0 | K25: =SUM(K23:K24) -> 0 | L25: =SUM(L23:L24) -> 0 | M25: =SUM(M23:M24) -> 0 | N25: =SUM(N23:N24) -> 0 | O25: =SUM(O23:O24) -> 0 | ... Q25: =SUM(Q23:Q24) -> 0 | R25: =Q25/Q37 -> #DIV/0! | U25: w/path | V25: cluster w | W25: int. path w | X25: =SUM(C47:C48)*2 -> 0 | Y25: =Y24 -> 0 | Z25: =Z24 -> 0 | AA25: =AA24 -> 0 | AB25: =AB24 -> 0 | AC25: =AC24 -> 0 | AD25: =AD24 -> 0 | AE25: =AE24 -> 0 | AF25: =AF24 -> 0 | ... AH25: =AH24 -> 0 | AK25: =AK24 -> 0 | AL25: =AL24 -> 0 | AM25: =IF(AA25=0,0,AL25/AA25) -> 0 | AO25: =AO24 -> 0 | AP25: =AP24 -> 0 | AQ25: =AQ24 -> 0 | AR25: =AO25*AG25 -> 0 | AS25: =AP25*AD25 -> 0 | AT25: =ROUND(AQ25*AK25,0) -> 0 | AU25: =AU24 -> 0
A26: Off-grid clusters | B26: on arteries | H26: 0 | I26: 0 | J26: 0 | K26: 0 | L26: 0 | M26: 0 | N26: =SUM(G26:M26) -> 0 | O26: 0 | P26: =SUM(N26:O26) -> 0 | Q26: =P26 -> 0 | R26: =Q26/Q37 -> #DIV/0! | T26: Off-grid clusters | U26: on arteries | V26: 0 | W26: 0 | X26: 0 | Y26: =(V26-W26)/2 -> 0 | Z26: 0 | AA26: =Z26*Y26 -> 0 | AB26: 0 | AC26: 0 | AD26: =Y26-AB26-AC26 -> 0 | AE26: 0 | AF26: =AE26 -> 0 | AG26: =Z26-2*AE26 -> 0 | AH26: =AG26*AD26 -> 0 | AI26: 0 | AJ26: 0 | AK26: =ROUND(AI26*(1+AJ26),0) -> 0 | AL26: =AG26*AD26*AK26 -> 0 | AM26: =IF(AA26=0,0,AL26/AA26) -> 0 | AO26: 0 | AP26: 0 | AQ26: 0 | AR26: =AO26*AG26 -> 0 | AS26: =AP26*AD26 -> 0 | AT26: =ROUND(AQ26*AK26,0) -> 0 | AU26: =AL26*AP26*AQ26 -> 0
A27: Off-grid clusters | B27: on secondaries | H27: 0 | I27: 0 | J27: 0 | K27: 0 | L27: 0 | M27: 0 | N27: =SUM(G27:M27) -> 0 | O27: 0 | P27: =SUM(N27:O27) -> 0 | Q27: =P27 -> 0 | R27: =Q27/Q37 -> #DIV/0! | T27: Off-grid clusters | U27: on secondaries | V27: =V28 -> 0 | W27: =W28 -> 0 | X27: 0 | Y27: =(V27-W27)/2 -> 0 | Z27: 0 | AA27: =Z27*Y27 -> 0 | AB27: 0 | AC27: 0 | AD27: =Y27-AB27-AC27 -> 0 | AE27: 0 | AF27: =AE27 -> 0 | AG27: =Z27-2*AE27 -> 0 | AH27: =AG27*AD27 -> 0 | AI27: =AI28 -> 0 | AJ27: 0 | AK27: =ROUND(AI27*(1+AJ27),0) -> 0 | AL27: =AG27*AD27*AK27 -> 0 | AM27: =IF(AA27=0,0,AL27/AA27) -> 0 | AO27: =AO28 -> 0 | AP27: =AP28 -> 0 | AQ27: =AQ28 -> 0 | AR27: =AO27*AG27 -> 0 | AS27: =AP27*AD27 -> 0 | AT27: =ROUND(AQ27*AK27,0) -> 0 | AU27: =AL27*AP27*AQ27 -> 0
A28: Simple off-grid clusters | B28: on locals | H28: 0 | I28: 0 | J28: 0 | K28: 0 | L28: 0 | M28: 0 | N28: =SUM(G28:M28) -> 0 | O28: 0 | P28: =SUM(N28:O28) -> 0 | Q28: =P28 -> 0 | R28: =Q28/Q37 -> #DIV/0! | T28: Simple off-grid clusters | U28: on locals | V28: 0 | W28: 0 | X28: 0 | Y28: =(V28-W28)/2 -> 0 | Z28: 0 | AA28: =Z28*Y28 -> 0 | AB28: 0 | AC28: 0 | AD28: =Y28-AB28-AC28 -> 0 | AE28: 0 | AF28: =AE28 -> 0 | AG28: =Z28-2*AE28 -> 0 | AH28: =AG28*AD28 -> 0 | AI28: 0 | AJ28: 0 | AK28: =ROUND(AI28*(1+AJ28),0) -> 0 | AL28: =AG28*AD28*AK28 -> 0 | AM28: =IF(AA28=0,0,AL28/AA28) -> 0 | AO28: 0 | AP28: 0 | AQ28: 0 | AR28: =AO28*AG28 -> 0 | AS28: =AP28*AD28 -> 0 | AT28: =ROUND(AQ28*AK28,0) -> 0 | AU28: =AL28*AP28*AQ28 -> 0
A29: 2-level off-grid clusters, 1st level | B29: on locals | H29: 0 | I29: 0 | J29: 0 | K29: 0 | L29: 0 | M29: 0 | N29: =SUM(G29:M29) -> 0 | O29: 0 | P29: =SUM(N29:O29) -> 0 | Q29: =P29 -> 0 | R29: =Q29/Q37 -> #DIV/0! | T29: 2-level off-grid clusters, 1st level | U29: on locals | V29: =V28 -> 0 | W29: =W28 -> 0 | X29: 0 | Y29: =Y28 -> 0 | Z29: =Z28 -> 0 | AA29: =AA28 -> 0 | AB29: =AB28 -> 0 | AC29: =AC28 -> 0 | AD29: =AD28 -> 0 | AE29: =AE28 -> 0 | AF29: =AF28 -> 0 | ... AH29: =AH28 -> 0 | AK29: =AK28 -> 0 | AL29: =AL28 -> 0 | AM29: =IF(AA29=0,0,AL29/AA29) -> 0 | AO29: =AO28 -> 0 | AP29: =AP28 -> 0 | AQ29: =AQ28 -> 0 | AR29: =AO29*AG29 -> 0 | AS29: =AP29*AD29 -> 0 | AT29: =ROUND(AQ29*AK29,0) -> 0 | AU29: =AU28 -> 0
A30: 2nd level | B30: from 1st | H30: 0 | I30: 0 | J30: 0 | K30: 0 | L30: 0 | M30: 0 | N30: =SUM(G30:M30) -> 0 | O30: 0 | P30: =SUM(N30:O30) -> 0 | Q30: =P30 -> 0 | R30: =Q30/Q37 -> #DIV/0! | T30: 2nd level | U30: from 1st | V30: =V28 -> 0 | W30: 0 | X30: 0 | Y30: =(V30-W30)/2 -> 0 | Z30: 0 | AA30: =Z30*Y30 -> 0 | AB30: =AB28 -> 0 | AC30: =AC28 -> 0 | AD30: =Y30-AB30-AC30 -> 0 | AE30: =AE28 -> 0 | AF30: =AE30 -> 0 | AG30: =Z30-2*AE30 -> 0 | AH30: =AG30*AD30 -> 0 | AI30: =AI28 -> 0 | AJ30: 0 | AK30: =ROUND(AI30*(1+AJ30),0) -> 0 | AL30: =AG30*AD30*AK30 -> 0 | AM30: =IF(AA30=0,0,AL30/AA30) -> 0 | AO30: 0 | AP30: 0 | AQ30: 0 | AR30: =AO30*AG30 -> 0 | AS30: =AP30*AD30 -> 0 | AT30: =ROUND(AQ30*AK30,0) -> 0 | AU30: =AL30*AP30*AQ30 -> 0
B31: Off-grid partitions, subtotal | H31: =SUM(H26:H30) -> 0 | I31: =SUM(I26:I30) -> 0 | J31: =SUM(J26:J30) -> 0 | K31: =SUM(K26:K30) -> 0 | L31: =SUM(L26:L30) -> 0 | M31: =SUM(M26:M30) -> 0 | N31: =SUM(N26:N30) -> 0 | O31: =SUM(O26:O30) -> 0 | ... Q31: =SUM(Q26:Q30) -> 0 | R31: =Q31/Q37 -> #DIV/0!
B32: Land in urban blocks, subtotal | C32: 0 | D32: 0 | E32: 0 | F32: 0 | G32: 0 | H32: =H31+H25+H22+H18 -> 0 | I32: =I31+I25+I22+I18 -> 0 | J32: =J31+J25+J22+J18 -> 0 | K32: =K31+K25+K22+K18 -> 0 | L32: =L31+L25+L22+L18 -> 0 | M32: =M31+M25+M22+M18 -> 0 | N32: =N31+N25+N22+N18 -> 0 | O32: =O31+O25+O22+O18 -> 0 | ... Q32: =Q31+Q25+Q22+Q18 -> 0 | R32: =Q32/Q37 -> #DIV/0!
B33: Arteries (main roads) | C33: 0 | D33: 0 | E33: 0 | F33: =SUM(C33:E33) -> 0 | G33: 0 | N33: =G33 -> 0 | P33: =SUM(N33:O33) -> 0 | Q33: =P33+F33 -> 0 | R33: =Q33/Q37 -> #DIV/0!
B34: Secondaries (distributor roads) | C34: 0 | D34: 0 | E34: 0 | F34: =SUM(C34:E34) -> 0 | G34: 0 | N34: =G34 -> 0 | P34: =SUM(N34:O34) -> 0 | Q34: =P34+F34 -> 0 | R34: =Q34/Q37 -> #DIV/0!
B35: Tertiaries (access and local roads) | C35: 0 | D35: 0 | E35: 0 | F35: =SUM(C35:E35) -> 0 | G35: 0 | N35: =G35 -> 0 | P35: =SUM(N35:O35) -> 0 | Q35: =P35+F35 -> 0 | R35: =Q35/Q37 -> #DIV/0!
B36: Land in public streets, subtotal | C36: =SUM(C33:C35) -> 0 | D36: =SUM(D33:D35) -> 0 | E36: =SUM(E33:E35) -> 0 | F36: =SUM(F33:F35) -> 0 | G36: =SUM(G33:G35) -> 0 | N36: =SUM(N33:N35) -> 0 | P36: =SUM(P33:P35) -> 0 | Q36: =SUM(Q33:Q35) -> 0 | R36: =Q36/Q37 -> #DIV/0!
B37: Totals | C37: =C36+C13 -> 0 | D37: =D36+D13 -> 0 | E37: =E36+E13 -> 0 | F37: =F36+F13 -> 0 | G37: =G32 -> 0 | H37: =H32 -> 0 | I37: =I32 -> 0 | J37: =J32 -> 0 | K37: =K32 -> 0 | L37: =L32 -> 0 | M37: =M32 -> 0 | N37: =N36+N32 -> 0 | O37: =O36+O32 -> 0 | P37: =P36+P32 -> 0 | Q37: =Q36+Q32+Q13 -> 0 | R37: =Q37/Q37 -> #DIV/0!
B38: Distribution (share of total) | C38: =C37/Q37 -> #DIV/0! | D38: =D37/Q37 -> #DIV/0! | E38: =E37/Q37 -> #DIV/0! | F38: =F37/Q37 -> #DIV/0! | G38: =G37/Q37 -> #DIV/0! | H38: =H37/Q37 -> #DIV/0! | I38: =I37/Q37 -> #DIV/0! | J38: =J37/Q37 -> #DIV/0! | K38: =K37/Q37 -> #DIV/0! | L38: =L37/Q37 -> #DIV/0! | M38: =M37/Q37 -> #DIV/0! | N38: =N37/Q37 -> #DIV/0! | O38: =O37/Q37 -> #DIV/0! | P38: =P37/Q37 -> #DIV/0! | Q38: =Q37/Q37 -> #DIV/0!
A43: Clusters
B44: Area | C44: Connections from public network | D44: Semi-private / collective infra | G44: access areas on on-grid partitions | H44: semi-private collective circulation | I44: semi-private collective green space
A45: Off-grid clusters | B45: on arteries | C45: 0 | D45: 0 | G45: 0 | H45: 0 | I45: 0
...

Sheet 1db
A1: Site mobilization proforma
A3: Trunk infrastructure items | B3: Base-year amount
A4: Off-site costs | B4: =-'1off-site'!G6 -> 0
A5: Off-site revenues | B5: ='1off-site'!G12 -> 0
A6: Off-site surplus (loss) | B6: ='1off-site'!G14 -> 0 | D6: formatting in case of surplus
A7: Off-site costs, project-borne | B7: ='1off-site'!G16 -> 0 | D7: =D6 -> formatting in case of surplus
A8: Site mobilization items | B8: Base-year amount
A9: ='1site'!B10 -> 0 | B9: =-'1site'!B30 -> 0
A10: ='1site'!C10 -> 0 | B10: =-'1site'!C30 -> 0
A11: ='1site'!D10 -> 0 | B11: =-'1site'!D30 -> 0
A12: ='1site'!E10 -> 0 | B12: =-'1site'!E30 -> 0
A13: ='1site'!F10 -> 0 | B13: =-'1site'!F30 -> 0
A14: Land costs, subtotal | B14: =-'1site'!G30 -> 0
A16: Site-related costs, total | B16: =B14+B7 -> 0 | D16: =D15 -> 0

Sheet 2db
A1: Neighborhood scale proforma
A3: Item | B3: Base-year amount | C3: quantity
A4: Land and site-related costs | B4: =-'2neighborhood'!L6 -> 0 | C4: ='2neighborhood'!D4 -> 0
A5: Arteries (main roads) | B5: =-'2neighborhood'!L11 -> 0 | C5: ='2neighborhood'!D8 -> 0
A6: Secondaries (distributor roads) | B6: =-'2neighborhood'!L15 -> 0 | C6: ='2neighborhood'!D12 -> 0
A7: Tertiaries (access and local roads) | B7: =-'2neighborhood'!L19 -> 0 | C7: ='2neighborhood'!D16 -> 0
A8: Public Spaces | B8: =-'2neighborhood'!L29 -> 0 | C8: =SUM('2neighborhood'!D26:D27)/10000 -> 0
A9: Costs, total | B9: =SUM(B4:B8) -> 0 | C9: =C4 -> 0
A10: Revenues from private lands on arteries | B10: ='2neighborhood'!L56 -> 0 | C10: ='2neighborhood'!K56/10000 -> 0
A11: ...on secondaries | B11: ='2neighborhood'!L60 -> 0 | C11: ='2neighborhood'!K60/10000 -> 0
A12: ...on tertiaries | B12: ='2neighborhood'!L63 -> 0 | C12: ='2neighborhood'!K63/10000 -> 0
A13: ...in off-grid clusters | B13: ='2neighborhood'!L71 -> 0 | C13: ='2neighborhood'!K71/10000 -> 0
A14: Revenues from private lands | B14: =SUM(B10:B13) -> 0 | C14: ='2neighborhood'!K76/10000 -> 0
A15: Revenue from public uses | B15: ='2neighborhood'!J82 -> 0 | C15: =C8 -> 0
A16: Revenues, total | B16: =SUM(B14:B15) -> 0 | C16: =SUM(C14:C15) -> 0
A18: Project surplus (loss) | B18: =B9+B16 -> 0 | C18: =C4 -> 0 | E18: formatting in case of loss
A19: Financial efficiency (surplus/costs) | B19: =-B18/B9 -> #DIV/0! | E19: formatting in case of loss
B22: differentiate social and private surplus?

Sheet 3db
A1: Off-grid Clusters Proforma
A3: Off-grid cluster category | B3: on arteries | C3: on secondaries | D3: on locals, single | E3: on locals, multiple | F3: total
A4: Number of clusters | B4: ='3cluster_artery'!B3 -> 0 | C4: ='3cluster_secondary'!B3 -> 0 | D4: ='3lcluster_local'!B3 -> 0 | E4: ='3lcluster_local_2level'!B3 -> 0 | F4: =SUM(B4:E4) -> 0
A5: Costs and revenues, all clusters | B5: Base-year amount | C5: Base-year amount | D5: Base-year amount | E5: Base-year amount | F5: Base-year amount
A6: Serviced land, all clusters | B6: =-'3cluster_artery'!I10 -> 0 | C6: =-'3cluster_secondary'!I10 -> 0 | D6: =-'3lcluster_local'!I10 -> 0 | E6: =-('3lcluster_local_2level'!I10+'3lcluster_local_2level'!I22) -> 0 | F6: =SUM(B6:E6) -> 0
A7: Semi-private (collective) space, all clusters | B7: =-'3cluster_artery'!I16 -> 0 | C7: =-'3cluster_secondary'!I16 -> 0 | D7: =-'3lcluster_local'!I16 -> 0 | E7: =-('3lcluster_local_2level'!I16+'3lcluster_local_2level'!I28) -> 0 | F7: =SUM(B7:E7) -> 0
A8: Total costs, all clusters | B8: =-'3cluster_artery'!I17 -> 0 | C8: =-'3cluster_secondary'!I17 -> 0 | D8: =-'3lcluster_local'!I17 -> 0 | E8: =-'3lcluster_local_2level'!I17-'3lcluster_local_2level'!I29 -> 0 | F8: =SUM(B8:E8) -> 0
A9: Revenues from private lots, all clusters | B9: ='3cluster_artery'!I23 -> 0 | C9: ='3cluster_secondary'!I23 -> 0 | D9: ='3lcluster_local'!I23 -> 0 | E9: ='3lcluster_local_2level'!I44+'3lcluster_local_2level'!I37 -> 0 | F9: =SUM(B9:E9) -> 0
A10: Other revenues, all clusters | B10: =SUM('3cluster_artery'!I24:I25) -> 0 | C10: =SUM('3cluster_secondary'!I24:I25) -> 0 | D10: =SUM('3lcluster_local'!I24:I25) -> 0 | E10: =SUM('3lcluster_local_2level'!I38:I39)+SUM('3lcluster_local_2level'!I45:I46) -> 0 | F10: =SUM(B10:E10) -> 0
A11: Total revenue, all clusters | B11: ='3cluster_artery'!I26 -> 0 | C11: ='3cluster_secondary'!I26 -> 0 | D11: ='3lcluster_local'!I26 -> 0 | E11: ='3lcluster_local_2level'!I47 -> 0 | F11: =SUM(B11:E11) -> 0
A13: Total surplus (loss), all clusters | B13: =B11+B8 -> 0 | C13: =C11+C8 -> 0 | D13: =D11+D8 -> 0 | E13: =E11+E8 -> 0 | F13: =F11+F8 -> 0 | H13: formatting in case of loss
A14: Financial efficiency (surplus/costs) | B14: =IF(B8=0,0,-B13/B8) -> 0 | C14: =IF(C8=0,0,-C13/C8) -> 0 | D14: =IF(D8=0,0,-D13/D8) -> 0 | E14: =IF(E8=0,0,-E13/E8) -> 0 | F14: =IF(F8=0,0,-F13/F8) -> 0 | H14: formatting in case of loss
A16: Off-grid cluster category | B16: on arteries | C16: on secondaries | D16: on locals, single | E16: on locals, multiple | F16: average
A17: Number of clusters | B17: =B4 -> 0 | C17: =C4 -> 0 | D17: =D4 -> 0 | E17: =E4 -> 0 | F17: =F4 -> 0
A18: Costs and revenues, individual cluster | B18: Base-year amount | C18: Base-year amount | D18: Base-year amount | E18: Base-year amount | F18: Base-year amount
A19: Serviced land | B19: =IF(B4=0,0,'3db'!B6/B4) -> 0 | C19: =IF(C4=0,0,'3db'!C6/C4) -> 0 | D19: =IF(D4=0,0,'3db'!D6/D4) -> 0 | E19: =IF(E4=0,0,'3db'!E6/E4) -> 0 | F19: =IF(F4=0,0,'3db'!F6/F4) -> 0
A20: Semi-private (collective) space | B20: =IF(B4=0,0,'3db'!B7/B4) -> 0 | C20: =IF(C4=0,0,'3db'!C7/C4) -> 0 | D20: =IF(D4=0,0,'3db'!D7/D4) -> 0 | E20: =IF(E4=0,0,'3db'!E7/E4) -> 0 | F20: =IF(F4=0,0,'3db'!F7/F4) -> 0
A21: Costs, total | B21: =IF(B4=0,0,'3db'!B8/B4) -> 0 | C21: =IF(C4=0,0,'3db'!C8/C4) -> 0 | D21: =IF(D4=0,0,'3db'!D8/D4) -> 0 | E21: =IF(E4=0,0,'3db'!E8/E4) -> 0 | F21: =IF(F4=0,0,'3db'!F8/F4) -> 0
A22: Revenues from private lots | B22: =IF(B4=0,0,'3db'!B9/B4) -> 0 | C22: =IF(C4=0,0,'3db'!C9/C4) -> 0 | D22: =IF(D4=0,0,'3db'!D9/D4) -> 0 | E22: =IF(E4=0,0,'3db'!E9/E4) -> 0 | F22: =IF(F4=0,0,'3db'!F9/F4) -> 0
A23: Other revenues | B23: =IF(B4=0,0,'3db'!B10/B4) -> 0 | C23: =IF(C4=0,0,'3db'!C10/C4) -> 0 | D23: =IF(D4=0,0,'3db'!D10/D4) -> 0 | E23: =IF(E4=0,0,'3db'!E10/E4) -> 0 | F23: =IF(F4=0,0,'3db'!F10/F4) -> 0
A24: Revenues, total | B24: =IF(B4=0,0,'3db'!B11/B4) -> 0 | C24: =IF(C4=0,0,'3db'!C11/C4) -> 0 | D24: =IF(D4=0,0,'3db'!D11/D4) -> 0 | E24: =IF(E4=0,0,'3db'!E11/E4) -> 0 | F24: =IF(F4=0,0,'3db'!F11/F4) -> 0
A26: Project surplus (loss) | B26: =IF(B4=0,0,'3db'!B13/B4) -> 0 | C26: =IF(C4=0,0,'3db'!C13/C4) -> 0 | D26: =IF(D4=0,0,'3db'!D13/D4) -> 0 | E26: =IF(E4=0,0,'3db'!E13/E4) -> 0 | F26: =IF(F4=0,0,'3db'!F13/F4) -> 0 | H26: formatting in case of loss
A27: Financial efficiency (surplus/costs) | B27: =IF(B21=0,0,-B26/B21) -> 0 | C27: =IF(C21=0,0,-C26/C21) -> 0 | D27: =IF(D21=0,0,-D26/D21) -> 0 | E27: =IF(E21=0,0,-E26/E21) -> 0 | F27: =IF(F21=0,0,-F26/F21) -> 0 | H27: formatting in case of loss

Sheet 4db
A1: Starter Buildings Proforma
A2: Location, by color code | B2: Artery x artery (corner) | C2: Artery x secondary (corner) | D2: Artery x tertiary (corner) | E2: Artery (regular) | F2: Artery (cluster access) | G2: Off-grid cluster (on arteries) | H2: Secondary x secondary (corner) | I2: Secondary x tertiary (corner) | J2: Secondary (regular) | K2: Secondary (cluster access) | L2: Off-grid cluster (secondaries) | M2: Tertiary x tertiary (corner) | N2: Tertiary (regular) | O2: Tertiary (cluster access) | P2: Off-grid cluster (simple) | Q2: 2-level cluster (1st level) | R2: 2-level cluster (2nd level) | S2: Total
A3: Serviced lots, withOUT construction | B3: =IF('4buildings'!B29=0,'4buildings'!B10,0) -> 0 | C3: =IF('4buildings'!C29=0,'4buildings'!C10,0) -> 0 | D3: =IF('4buildings'!D29=0,'4buildings'!D10,0) -> 0 | E3: =IF('4buildings'!E29=0,'4buildings'!E10,0) -> 0 | F3: =IF('4buildings'!F29=0,'4buildings'!F10,0) -> 0 | G3: =IF('4buildings'!G29=0,'4buildings'!G10,0) -> 0 | H3: =IF('4buildings'!H29=0,'4buildings'!H10,0) -> 0 | I3: =IF('4buildings'!I29=0,'4buildings'!I10,0) -> 0 | ... R3: =IF('4buildings'!R29=0,'4buildings'!R10,0) -> 0 | S3: =SUM(B3:R3) -> 0
A4: Costs and revenues | B4: Base-year amount | C4: Base-year amount | D4: Base-year amount | E4: Base-year amount | F4: Base-year amount | G4: Base-year amount | H4: Base-year amount | I4: Base-year amount | J4: Base-year amount | K4: Base-year amount | L4: Base-year amount | M4: Base-year amount | N4: Base-year amount | O4: Base-year amount | P4: Base-year amount | Q4: Base-year amount | R4: Base-year amount | S4: Base-year amount
A5: Serviced lots, on arteries | B5: =B3*'4buildings'!B35 -> 0 | C5: =C3*'4buildings'!C35 -> 0 | D5: =D3*'4buildings'!D35 -> 0 | E5: =E3*'4buildings'!E35 -> 0 | F5: =F3*'4buildings'!F35 -> 0 | S5: =SUM(B5:R5) -> 0
A6: …in off-grid clusters, from arteries | G6: =G3*'4buildings'!G35 -> 0 | S6: =SUM(B6:R6) -> 0
A7: Serviced lots, on secondaries | H7: =H3*'4buildings'!H35 -> 0 | I7: =I3*'4buildings'!I35 -> 0 | J7: =J3*'4buildings'!J35 -> 0 | K7: =K3*'4buildings'!K35 -> 0 | S7: =SUM(B7:R7) -> 0
A8: …in off-grid clusters, from secondaries | L8: =L3*'4buildings'!L35 -> 0 | S8: =SUM(B8:R8) -> 0
A9: Serviced lots, on locals | M9: =M3*'4buildings'!M35 -> 0 | N9: =N3*'4buildings'!N35 -> 0 | O9: =O3*'4buildings'!O35 -> 0 | S9: =SUM(B9:R9) -> 0
A10: …in off-grid clusters, from locals | P10: =P3*'4buildings'!P35 -> 0 | Q10: =Q3*'4buildings'!Q35 -> 0 | R10: =R3*'4buildings'!R35 -> 0 | S10: =SUM(B10:R10) -> 0
A11: Sales of serviced lots, subtotal | B11: =B5 -> 0 | C11: =C5 -> 0 | D11: =D5 -> 0 | E11: =E5 -> 0 | F11: =F5 -> 0 | G11: =G6 -> 0 | H11: =H7 -> 0 | I11: =I7 -> 0 | J11: =J7 -> 0 | K11: =K7 -> 0 | L11: =L8 -> 0 | M11: =M9 -> 0 | N11: =N9 -> 0 | O11: =O9 -> 0 | P11: =P10 -> 0 | Q11: =Q10 -> 0 | R11: =R10 -> 0 | S11: =SUM(B11:R11) -> 0
A13: Serviced lots, WITH starters | B13: =IF('4buildings'!B29=0,0,'4buildings'!B10) -> 0 | C13: =IF('4buildings'!C29=0,0,'4buildings'!C10) -> 0 | D13: =IF('4buildings'!D29=0,0,'4buildings'!D10) -> 0 | E13: =IF('4buildings'!E29=0,0,'4buildings'!E10) -> 0 | F13: =IF('4buildings'!F29=0,0,'4buildings'!F10) -> 0 | G13: =IF('4buildings'!G29=0,0,'4buildings'!G10) -> 0 | H13: =IF('4buildings'!H29=0,0,'4buildings'!H10) -> 0 | I13: =IF('4buildings'!I29=0,0,'4buildings'!I10) -> 0 | ... R13: =IF('4buildings'!R29=0,0,'4buildings'!R10) -> 0 | S13: =SUM(B13:R13) -> 0
A14: Costs and revenues | B14: Base-year amount | C14: Base-year amount | D14: Base-year amount | E14: Base-year amount | F14: Base-year amount | G14: Base-year amount | H14: Base-year amount | I14: Base-year amount | J14: Base-year amount | K14: Base-year amount | L14: Base-year amount | M14: Base-year amount | N14: Base-year amount | O14: Base-year amount | P14: Base-year amount | Q14: Base-year amount | R14: Base-year amount | S14: Base-year amount
A15: Serviced lot | B15: =-B13*'4buildings'!B17 -> 0 | C15: =-C13*'4buildings'!C17 -> 0 | D15: =-D13*'4buildings'!D17 -> 0 | E15: =-E13*'4buildings'!E17 -> 0 | F15: =-F13*'4buildings'!F17 -> 0 | G15: =-G13*'4buildings'!G17 -> 0 | H15: =-H13*'4buildings'!H17 -> 0 | I15: =-I13*'4buildings'!I17 -> 0 | ... R15: =-R13*'4buildings'!R17 -> 0 | S15: =SUM(B15:R15) -> 0
A16: Construction | B16: =-B13*'4buildings'!B29 -> 0 | C16: =-C13*'4buildings'!C29 -> 0 | D16: =-D13*'4buildings'!D29 -> 0 | E16: =-E13*'4buildings'!E29 -> 0 | F16: =-F13*'4buildings'!F29 -> 0 | G16: =-G13*'4buildings'!G29 -> 0 | H16: =-H13*'4buildings'!H29 -> 0 | I16: =-I13*'4buildings'!I29 -> 0 | ... R16: =-R13*'4buildings'!R29 -> 0 | S16: =SUM(B16:R16) -> 0
A17: Interest | B17: =B13*('4buildings'!B31-'4buildings'!B33) -> 0 | C17: =C13*('4buildings'!C31-'4buildings'!C33) -> 0 | D17: =D13*('4buildings'!D31-'4buildings'!D33) -> 0 | E17: =E13*('4buildings'!E31-'4buildings'!E33) -> 0 | F17: =F13*('4buildings'!F31-'4buildings'!F33) -> 0 | G17: =G13*('4buildings'!G31-'4buildings'!G33) -> 0 | H17: =H13*('4buildings'!H31-'4buildings'!H33) -> 0 | I17: =I13*('4buildings'!I31-'4buildings'!I33) -> 0 | ... R17: =R13*('4buildings'!R31-'4buildings'!R33) -> 0 | S17: =SUM(B17:R17) -> 0
A18: Costs, total | B18: =SUM(B15:B17) -> 0 | C18: =SUM(C15:C17) -> 0 | D18: =SUM(D15:D17) -> 0 | E18: =SUM(E15:E17) -> 0 | F18: =SUM(F15:F17) -> 0 | G18: =SUM(G15:G17) -> 0 | H18: =SUM(H15:H17) -> 0 | I18: =SUM(I15:I17) -> 0 | ... R18: =SUM(R15:R17) -> 0 | S18: =SUM(B18:R18) -> 0
A19: Revenues (sales), commercial floor area | B19: =B13*'4buildings'!B46 -> 0 | C19: =C13*'4buildings'!C46 -> 0 | D19: =D13*'4buildings'!D46 -> 0 | E19: =E13*'4buildings'!E46 -> 0 | F19: =F13*'4buildings'!F46 -> 0 | G19: =G13*'4buildings'!G46 -> 0 | H19: =H13*'4buildings'!H46 -> 0 | I19: =I13*'4buildings'!I46 -> 0 | ... R19: =R13*'4buildings'!R46 -> 0 | S19: =SUM(B19:R19) -> 0
A20: Revenues (sales), residential floor area | B20: =B13*'4buildings'!B48 -> 0 | C20: =C13*'4buildings'!C48 -> 0 | D20: =D13*'4buildings'!D48 -> 0 | E20: =E13*'4buildings'!E48 -> 0 | F20: =F13*'4buildings'!F48 -> 0 | G20: =G13*'4buildings'!G48 -> 0 | H20: =H13*'4buildings'!H48 -> 0 | I20: =I13*'4buildings'!I48 -> 0 | ... R20: =R13*'4buildings'!R48 -> 0 | S20: =SUM(B20:R20) -> 0
A21: Revenues, total | B21: =B13*'4buildings'!B35 -> 0 | C21: =C13*'4buildings'!C35 -> 0 | D21: =D13*'4buildings'!D35 -> 0 | E21: =E13*'4buildings'!E35 -> 0 | F21: =F13*'4buildings'!F35 -> 0 | G21: =G13*'4buildings'!G35 -> 0 | H21: =H13*'4buildings'!H35 -> 0 | I21: =I13*'4buildings'!I35 -> 0 | ... R21: =R13*'4buildings'!R35 -> 0 | S21: =SUM(B21:R21) -> 0
A22: Project surplus (loss), per lot | B22: =B21+B18 -> 0 | C22: =C21+C18 -> 0 | D22: =D21+D18 -> 0 | E22: =E21+E18 -> 0 | F22: =F21+F18 -> 0 | G22: =G21+G18 -> 0 | H22: =H21+H18 -> 0 | I22: =I21+I18 -> 0 | ... R22: =R21+R18 -> 0 | S22: =SUM(B22:R22) -> 0 | U22: formatting in case of loss
A23: Financial efficiency (surplus/costs) | B23: =IF(B18=0,0,-B22/B18) -> 0 | C23: =IF(C18=0,0,-C22/C18) -> 0 | D23: =IF(D18=0,0,-D22/D18) -> 0 | E23: =IF(E18=0,0,-E22/E18) -> 0 | F23: =IF(F18=0,0,-F22/F18) -> 0 | G23: =IF(G18=0,0,-G22/G18) -> 0 | H23: =IF(H18=0,0,-H22/H18) -> 0 | I23: =IF(I18=0,0,-I22/I18) -> 0 | ... S23: =IF(S18=0,0,-S22/S18) -> 0 | U23: formatting in case of loss
A25: ="@Daniel, in the standard dashboard view only show the last column with totals, please." -> @Daniel, in the standard dashboard view only show the last column with totals, please.

Sheet 5db
A1: Dwellings Proforma & Affordability
A3: Location, by color code | B3: Artery x artery (corner) | C3: Artery x secondary (corner) | D3: Artery x tertiary (corner) | E3: Artery (regular) | F3: Artery (cluster access) | G3: Off-grid cluster (on arteries) | H3: Secondary x secondary (corner) | I3: Secondary x tertiary (corner) | J3: Secondary (regular) | K3: Secondary (cluster access) | L3: Off-grid cluster (secondaries) | M3: Tertiary x tertiary (corner) | N3: Tertiary (regular) | O3: Tertiary (cluster access) | P3: Off-grid cluster (simple) | Q3: 2-level cluster (1st level) | R3: 2-level cluster (2nd level) | S3: Total OR min. to max.
A4: Serviced lots WITH starters | B4: =IF('4buildings'!B29=0,0,'4buildings'!B10) -> 0 | C4: =IF('4buildings'!C29=0,0,'4buildings'!C10) -> 0 | D4: =IF('4buildings'!D29=0,0,'4buildings'!D10) -> 0 | E4: =IF('4buildings'!E29=0,0,'4buildings'!E10) -> 0 | F4: =IF('4buildings'!F29=0,0,'4buildings'!F10) -> 0 | G4: =IF('4buildings'!G29=0,0,'4buildings'!G10) -> 0 | H4: =IF('4buildings'!H29=0,0,'4buildings'!H10) -> 0 | I4: =IF('4buildings'!I29=0,0,'4buildings'!I10) -> 0 | ... R4: =IF('4buildings'!R29=0,0,'4buildings'!R10) -> 0 | S4: =SUM(B4:R4) -> 0
A5: Starter units (incl. sublets), project-built | B5: =IF(B4=0,0,B4*'5dwellings'!B20) -> 0 | C5: =IF(C4=0,0,C4*'5dwellings'!C20) -> 0 | D5: =IF(D4=0,0,D4*'5dwellings'!D20) -> 0 | E5: =IF(E4=0,0,E4*'5dwellings'!E20) -> 0 | F5: =IF(F4=0,0,F4*'5dwellings'!F20) -> 0 | G5: =IF(G4=0,0,G4*'5dwellings'!G20) -> 0 | H5: =IF(H4=0,0,H4*'5dwellings'!H20) -> 0 | I5: =IF(I4=0,0,I4*'5dwellings'!I20) -> 0 | ... R5: =IF(R4=0,0,R4*'5dwellings'!R20) -> 0 | S5: =SUM(B5:R5) -> 0
A6: ='5finance'!A3 -> Starter type | B6: ='5finance'!B3 -> lot only | C6: ='5finance'!C3 -> lot only | D6: ='5finance'!D3 -> lot only | E6: ='5finance'!E3 -> mixed-use building | F6: ='5finance'!F3 -> mixed-use building | G6: ='5finance'!G3 -> lot only | H6: ='5finance'!H3 -> lot only | ... R6: ='5finance'!R3 -> roof
A7: ='5finance'!A4 -> starter dwelling main units (owned), average gross area | B7: ='5finance'!B4 -> 0 | C7: ='5finance'!C4 -> 0 | D7: ='5finance'!D4 -> 0 | E7: ='5finance'!E4 -> 0 | F7: ='5finance'!F4 -> 0 | G7: ='5finance'!G4 -> 0 | H7: ='5finance'!H4 -> 0 | ... R7: ='5finance'!R4 -> 0 | S7: =MIN(B27:R27) -> 0 | T7: to | U7: =ROUND(MAX(B7:R7),0) -> 0
A8: Costs | B8: Base-year amount | C8: Base-year amount | D8: Base-year amount | E8: Base-year amount | F8: Base-year amount | G8: Base-year amount | H8: Base-year amount | I8: Base-year amount | J8: Base-year amount | K8: Base-year amount | L8: Base-year amount | M8: Base-year amount | N8: Base-year amount | O8: Base-year amount | P8: Base-year amount | Q8: Base-year amount | R8: Base-year amount | S8: min | T8: to | U8: max
A9: ='5finance'!A5 -> Land cost, attributed to 1 main dwelling unit | B9: ='5finance'!B5 -> 0 | C9: ='5finance'!C5 -> 0 | D9: ='5finance'!D5 -> 0 | E9: ='5finance'!E5 -> 0 | F9: ='5finance'!F5 -> 0 | G9: ='5finance'!G5 -> 0 | H9: ='5finance'!H5 -> 0 | ... R9: ='5finance'!R5 -> 0 | S9: =MIN(B29:R29) -> 0 | T9: to | U9: =ROUND(MAX(B9:R9),0) -> 0
A10: ='5finance'!A6 -> Starter unit cost, attributed to 1 main dwelling unit | B10: ='5finance'!B6 -> 0 | C10: ='5finance'!C6 -> 0 | D10: ='5finance'!D6 -> 0 | E10: ='5finance'!E6 -> 0 | F10: ='5finance'!F6 -> 0 | G10: ='5finance'!G6 -> 0 | H10: ='5finance'!H6 -> 0 | ... R10: ='5finance'!R6 -> 0 | S10: =MIN(B30:R30) -> 0 | T10: to | U10: =ROUND(MAX(B10:R10),0) -> 0
A11: ='5finance'!A7 -> Additional household investment, before move in (if any) | B11: =IF(B7=0,0,'5finance'!B7) -> 0 | C11: =IF(C7=0,0,'5finance'!C7) -> 0 | D11: =IF(D7=0,0,'5finance'!D7) -> 0 | E11: =IF(E7=0,0,'5finance'!E7) -> 0 | F11: =IF(F7=0,0,'5finance'!F7) -> 0 | G11: =IF(G7=0,0,'5finance'!G7) -> 0 | H11: =IF(H7=0,0,'5finance'!H7) -> 0 | I11: =IF(I7=0,0,'5finance'!I7) -> 0 | ... R11: =IF(R7=0,0,'5finance'!R7) -> 0 | S11: =MIN(B31:R31) -> 0 | T11: to | U11: =ROUND(MAX(B11:R11),0) -> 0
A12: ='5finance'!A8 -> Total cost, to be financed | B12: ='5finance'!B8 -> 0 | C12: ='5finance'!C8 -> 0 | D12: ='5finance'!D8 -> 0 | E12: ='5finance'!E8 -> 0 | F12: ='5finance'!F8 -> 0 | G12: ='5finance'!G8 -> 0 | H12: ='5finance'!H8 -> 0 | ... R12: ='5finance'!R8 -> 0 | S12: =MIN(B32:R32) -> 0 | T12: to | U12: =ROUND(MAX(B12:R12),0) -> 0
A14: Required monthly payments | B14: Monthly payments | C14: Monthly payments | D14: Monthly payments | E14: Monthly payments | F14: Monthly payments | G14: Monthly payments | H14: Monthly payments | I14: Monthly payments | J14: Monthly payments | K14: Monthly payments | L14: Monthly payments | M14: Monthly payments | N14: Monthly payments | O14: Monthly payments | P14: Monthly payments | Q14: Monthly payments | R14: Monthly payments | S14: min | T14: to | U14: max
A15: Payments for land, if separate | B15: ='5finance'!B57 -> 0 | C15: ='5finance'!C57 -> 0 | D15: ='5finance'!D57 -> 0 | E15: ='5finance'!E57 -> 0 | F15: ='5finance'!F57 -> 0 | G15: ='5finance'!G57 -> 0 | H15: ='5finance'!H57 -> 0 | I15: ='5finance'!I57 -> 0 | ... R15: ='5finance'!R57 -> 0 | S15: =MIN(B35:R35) -> 0 | T15: to | U15: =ROUND(MAX(B15:R15),0) -> 0
A16: Payments for starter, if separate | B16: ='5finance'!B58 -> 0 | C16: ='5finance'!C58 -> 0 | D16: ='5finance'!D58 -> 0 | E16: ='5finance'!E58 -> 0 | F16: ='5finance'!F58 -> 0 | G16: ='5finance'!G58 -> 0 | H16: ='5finance'!H58 -> 0 | I16: ='5finance'!I58 -> 0 | ... R16: ='5finance'!R58 -> 0 | S16: =MIN(B36:R36) -> 0 | T16: to | U16: =ROUND(MAX(B16:R16),0) -> 0
A17: Payments, remaining | B17: ='5finance'!B59 -> 0 | C17: ='5finance'!C59 -> 0 | D17: ='5finance'!D59 -> 0 | E17: ='5finance'!E59 -> 0 | F17: ='5finance'!F59 -> 0 | G17: ='5finance'!G59 -> 0 | H17: ='5finance'!H59 -> 0 | I17: ='5finance'!I59 -> 0 | ... R17: ='5finance'!R59 -> 0 | S17: =MIN(B37:R37) -> 0 | T17: to | U17: =ROUND(MAX(B17:R17),0) -> 0
A18: Payments, total | B18: =SUM(B15:B16) -> 0 | C18: =SUM(C15:C16) -> 0 | D18: =SUM(D15:D16) -> 0 | E18: =SUM(E15:E16) -> 0 | F18: =SUM(F15:F16) -> 0 | G18: =SUM(G15:G16) -> 0 | H18: =SUM(H15:H16) -> 0 | I18: =SUM(I15:I16) -> 0 | ... L18: =SUM(L15:L16) -> 0 | M18: ='5finance'!M60 -> 0 | N18: ='5finance'!N60 -> 0 | O18: ='5finance'!O60 -> 0 | P18: ='5finance'!P60 -> 0 | Q18: ='5finance'!Q60 -> 0 | R18: ='5finance'!R60 -> 0 | S18: =MIN(B38:R38) -> 0 | T18: to | U18: =ROUND(MAX(B18:R18),0) -> 0
A20: Affordability of ownership | B20: ='5affordability'!H21 -> 0 | C20: ='5affordability'!I21 -> 0 | D20: ='5affordability'!J21 -> 0 | E20: ='5affordability'!K21 -> 0 | F20: ='5affordability'!L21 -> 0 | G20: ='5affordability'!M21 -> 0 | H20: ='5affordability'!N21 -> 0 | I20: ='5affordability'!O21 -> 0 | ... S20: ='5affordability'!Y21 -> 0
A21: Affordability of rental sublets | B21: ='5affordability'!H38 -> 0 | C21: ='5affordability'!I38 -> 0 | D21: ='5affordability'!J38 -> 0 | E21: ='5affordability'!K38 -> 0 | F21: ='5affordability'!L38 -> 0 | G21: ='5affordability'!M38 -> 0 | H21: ='5affordability'!N38 -> 0 | I21: ='5affordability'!O38 -> 0 | ... S21: ='5affordability'!Y38 -> 0
A23: ="@Daniel, in the standard dashboard view only show the last column with totals. Beyond that, could we construct a dropdown menu, with the column headers, in order to display different columns?" -> @Daniel, in the standard dashboard view only show the last column with totals. Beyond that, could we construct a dropdown menu, with the column headers, in order to display different columns?
A24: ="@Daniel, if the CONCATE formula in the final column does not work for Lucky Sheets, this can be hardcoded for RUE?" -> @Daniel, if the CONCATE formula in the final column does not work for Lucky Sheets, this can be hardcoded for RUE?
A26: Workaround area for minimum calculation, excluding cells, of which the value is zero…
A27: ='5finance'!A30 -> Downpayment, share | B27: =IF(B7=0,U7,B7) -> 0 | C27: =IF(C7=0,U7,C7) -> 0 | D27: =IF(D7=0,U7,D7) -> 0 | E27: =IF(E7=0,U7,E7) -> 0 | F27: =IF(F7=0,U7,F7) -> 0 | G27: =IF(G7=0,U7,G7) -> 0 | H27: =IF(H7=0,U7,H7) -> 0 | I27: =IF(I7=0,U7,I7) -> 0 | J27: =IF(J7=0,U7,J7) -> 0 | K27: =IF(K7=0,U7,K7) -> 0 | L27: =IF(L7=0,U7,L7) -> 0 | M27: =IF(M7=0,U7,M7) -> 0 | N27: =IF(N7=0,U7,N7) -> 0 | O27: =IF(O7=0,U7,O7) -> 0 | P27: =IF(P7=0,U7,P7) -> 0 | Q27: =IF(Q7=0,U7,Q7) -> 0 | R27: =IF(R7=0,U7,R7) -> 0
A28: Costs and revenues
A29: ='5finance'!A31 -> …, amount | B29: =IF(B9=0,U9,B9) -> 0 | C29: =IF(C9=0,U9,C9) -> 0 | D29: =IF(D9=0,U9,D9) -> 0 | E29: =IF(E9=0,U9,E9) -> 0 | F29: =IF(F9=0,U9,F9) -> 0 | G29: =IF(G9=0,U9,G9) -> 0 | H29: =IF(H9=0,U9,H9) -> 0 | I29: =IF(I9=0,U9,I9) -> 0 | J29: =IF(J9=0,U9,J9) -> 0 | K29: =IF(K9=0,U9,K9) -> 0 | L29: =IF(L9=0,U9,L9) -> 0 | M29: =IF(M9=0,U9,M9) -> 0 | N29: =IF(N9=0,U9,N9) -> 0 | O29: =IF(O9=0,U9,O9) -> 0 | P29: =IF(P9=0,U9,P9) -> 0 | Q29: =IF(Q9=0,U9,Q9) -> 0 | R29: =IF(R9=0,U9,R9) -> 0
A30: ='5finance'!A32 -> Downpayment/cash subsidy | B30: =IF(B10=0,U10,B10) -> 0 | C30: =IF(C10=0,U10,C10) -> 0 | D30: =IF(D10=0,U10,D10) -> 0 | E30: =IF(E10=0,U10,E10) -> 0 | F30: =IF(F10=0,U10,F10) -> 0 | G30: =IF(G10=0,U10,G10) -> 0 | H30: =IF(H10=0,U10,H10) -> 0 | I30: =IF(I10=0,U10,I10) -> 0 | J30: =IF(J10=0,U10,J10) -> 0 | K30: =IF(K10=0,U10,K10) -> 0 | L30: =IF(L10=0,U10,L10) -> 0 | M30: =IF(M10=0,U10,M10) -> 0 | N30: =IF(N10=0,U10,N10) -> 0 | O30: =IF(O10=0,U10,O10) -> 0 | P30: =IF(P10=0,U10,P10) -> 0 | Q30: =IF(Q10=0,U10,Q10) -> 0 | R30: =IF(R10=0,U10,R10) -> 0
A31: ='5finance'!A33 -> Amount to be financed | B31: =IF(B11=0,U11,B11) -> 0 | C31: =IF(C11=0,U11,C11) -> 0 | D31: =IF(D11=0,U11,D11) -> 0 | E31: =IF(E11=0,U11,E11) -> 0 | F31: =IF(F11=0,U11,F11) -> 0 | G31: =IF(G11=0,U11,G11) -> 0 | H31: =IF(H11=0,U11,H11) -> 0 | I31: =IF(I11=0,U11,I11) -> 0 | J31: =IF(J11=0,U11,J11) -> 0 | K31: =IF(K11=0,U11,K11) -> 0 | L31: =IF(L11=0,U11,L11) -> 0 | M31: =IF(M11=0,U11,M11) -> 0 | N31: =IF(N11=0,U11,N11) -> 0 | O31: =IF(O11=0,U11,O11) -> 0 | P31: =IF(P11=0,U11,P11) -> 0 | Q31: =IF(Q11=0,U11,Q11) -> 0 | R31: =IF(R11=0,U11,R11) -> 0
A32: ='5finance'!A34 -> Financing period, months | B32: =IF(B12=0,U12,B12) -> 0 | C32: =IF(C12=0,U12,C12) -> 0 | D32: =IF(D12=0,U12,D12) -> 0 | E32: =IF(E12=0,U12,E12) -> 0 | F32: =IF(F12=0,U12,F12) -> 0 | G32: =IF(G12=0,U12,G12) -> 0 | H32: =IF(H12=0,U12,H12) -> 0 | I32: =IF(I12=0,U12,I12) -> 0 | J32: =IF(J12=0,U12,J12) -> 0 | K32: =IF(K12=0,U12,K12) -> 0 | L32: =IF(L12=0,U12,L12) -> 0 | M32: =IF(M12=0,U12,M12) -> 0 | N32: =IF(N12=0,U12,N12) -> 0 | O32: =IF(O12=0,U12,O12) -> 0 | P32: =IF(P12=0,U12,P12) -> 0 | Q32: =IF(Q12=0,U12,Q12) -> 0 | R32: =IF(R12=0,U12,R12) -> 0
A34: Monthly payments
A35: Payments for land, if separate | B35: =IF(B15=0,U15,B15) -> 0 | C35: =IF(C15=0,U15,C15) -> 0 | D35: =IF(D15=0,U15,D15) -> 0 | E35: =IF(E15=0,U15,E15) -> 0 | F35: =IF(F15=0,U15,F15) -> 0 | G35: =IF(G15=0,U15,G15) -> 0 | H35: =IF(H15=0,U15,H15) -> 0 | I35: =IF(I15=0,U15,I15) -> 0 | J35: =IF(J15=0,U15,J15) -> 0 | K35: =IF(K15=0,U15,K15) -> 0 | L35: =IF(L15=0,U15,L15) -> 0 | M35: =IF(M15=0,U15,M15) -> 0 | N35: =IF(N15=0,U15,N15) -> 0 | O35: =IF(O15=0,U15,O15) -> 0 | P35: =IF(P15=0,U15,P15) -> 0 | Q35: =IF(Q15=0,U15,Q15) -> 0 | R35: =IF(R15=0,U15,R15) -> 0
A36: Payments for starter, if separate | B36: =IF(B16=0,U16,B16) -> 0 | C36: =IF(C16=0,U16,C16) -> 0 | D36: =IF(D16=0,U16,D16) -> 0 | E36: =IF(E16=0,U16,E16) -> 0 | F36: =IF(F16=0,U16,F16) -> 0 | G36: =IF(G16=0,U16,G16) -> 0 | H36: =IF(H16=0,U16,H16) -> 0 | I36: =IF(I16=0,U16,I16) -> 0 | J36: =IF(J16=0,U16,J16) -> 0 | K36: =IF(K16=0,U16,K16) -> 0 | L36: =IF(L16=0,U16,L16) -> 0 | M36: =IF(M16=0,U16,M16) -> 0 | N36: =IF(N16=0,U16,N16) -> 0 | O36: =IF(O16=0,U16,O16) -> 0 | P36: =IF(P16=0,U16,P16) -> 0 | Q36: =IF(Q16=0,U16,Q16) -> 0 | R36: =IF(R16=0,U16,R16) -> 0
A37: Payments, remaining | B37: =IF(B17=0,U17,B17) -> 0 | C37: =IF(C17=0,U17,C17) -> 0 | D37: =IF(D17=0,U17,D17) -> 0 | E37: =IF(E17=0,U17,E17) -> 0 | F37: =IF(F17=0,U17,F17) -> 0 | G37: =IF(G17=0,U17,G17) -> 0 | H37: =IF(H17=0,U17,H17) -> 0 | I37: =IF(I17=0,U17,I17) -> 0 | J37: =IF(J17=0,U17,J17) -> 0 | K37: =IF(K17=0,U17,K17) -> 0 | L37: =IF(L17=0,U17,L17) -> 0 | M37: =IF(M17=0,U17,M17) -> 0 | N37: =IF(N17=0,U17,N17) -> 0 | O37: =IF(O17=0,U17,O17) -> 0 | P37: =IF(P17=0,U17,P17) -> 0 | Q37: =IF(Q17=0,U17,Q17) -> 0 | R37: =IF(R17=0,U17,R17) -> 0
A38: Payments, total | B38: =IF(B18=0,U18,B18) -> 0 | C38: =IF(C18=0,U18,C18) -> 0 | D38: =IF(D18=0,U18,D18) -> 0 | E38: =IF(E18=0,U18,E18) -> 0 | F38: =IF(F18=0,U18,F18) -> 0 | G38: =IF(G18=0,U18,G18) -> 0 | H38: =IF(H18=0,U18,H18) -> 0 | I38: =IF(I18=0,U18,I18) -> 0 | J38: =IF(J18=0,U18,J18) -> 0 | K38: =IF(K18=0,U18,K18) -> 0 | L38: =IF(L18=0,U18,L18) -> 0 | M38: =IF(M18=0,U18,M18) -> 0 | N38: =IF(N18=0,U18,N18) -> 0 | O38: =IF(O18=0,U18,O18) -> 0 | P38: =IF(P18=0,U18,P18) -> 0 | Q38: =IF(Q18=0,U18,Q18) -> 0 | R38: =IF(R18=0,U18,R18) -> 0

Sheet 6db
A1: Demographic forecast
A3: Initial dwellings | B3: ='6demographics'!S5 -> 0
A4: ...population | B4: ='6demographics'!S8 -> 0
A5: ...density, gross (all site) | B5: ='6demographics'!S9 -> 0
A6: ...density, net (private land) | B6: ='6demographics'!S10 -> 0
A8: Consolidated dwellings | B8: ='6demographics'!T6 -> 0
A9: ...population | B9: ='6demographics'!T8 -> 0
A10: ...density, gross (all site) | B10: ='6demographics'!T9 -> 0
A11: ...density, net (private land) | B11: ='6demographics'!T10 -> 0

Sheet spider
A1: Spider
A3: category | B3: key value | C3: objective (10 points) | D3: score (out of 10) | E3: Comment
A4: Sustainability:
A5: Land consumption | B5: =10000/'6db'!B10 -> #DIV/0! | C5: =10000/C8 -> 12.5 | D5: =C5/B5*10 -> #DIV/0! | E5: gross ratio for consolidated settlement
A6: Livability
A7: Density, initial | B7: ='6db'!B5 -> 0 | C7: 400 | D7: =B7/C7*10 -> 0 | E7: initial density for gross area
A8: Density, consolidated | B8: ='6db'!B10 -> 0 | C8: 800 | D8: =B8/C8*10 -> 0
A9: Public space (streets, open space & amenities), consolidated | B9: =Q!N38*B5 -> #DIV/0! | C9: =IF(B8>O30,P36,IF(B8>N30,O36,IF(B8>M30,N36,IF(B8>L30,M36,IF(B8>K30,L36,IF(B8>J30,K36,IF(B8>I30,J36,IF(B8>H30,I36,H36)))))))) -> 13 | D9: =B9/C9*10 -> #DIV/0!
A10: Public and community space | B10: =(Q!N37+SUM(Q!G45:I49))/Q!Q37*B5 -> #DIV/0! | C10: =C9 -> 13 | D10: =B10/C10*10 -> #DIV/0! | E10: streets, public open spaces, amenities; collective spaces in clusters per capita for consolidated (fully populated) settlement; for moving targets see below.
A11: Financial viability:
A12: Financial efficiency, neighborhood scale | B12: ='2db'!B19 -> #DIV/0! | C12: 0.15 | D12: =B12/C12*10 -> #DIV/0! | E12: (revenues-cost)/cost
A13: Financial efficiency, cluster scale | B13: ='3db'!F14 -> 0 | C13: 0.15 | D13: =B13/C13*10 -> 0 | E13: (revenues-cost)/cost
A14: Financial efficiency, building scale | B14: ='4db'!S23 -> 0 | C14: 0.15 | D14: =B14/C14*10 -> 0 | E14: (revenues-cost)/cost
A15: Inclusion:
A16: Affordability of ownership | B16: ='5affordability'!Y21 -> 0 | C16: 1 | D16: =B16/C16*10 -> 0 | E16: affordability of monthly payment (loan installment) and downpayment (first installment)
A17: Affordability of small-scale private rental | B17: ='5affordability'!Y38 -> 0 | C17: 1 | D17: =B17/C17*10 -> 0 | E17: affordability of monthly payment (rent) for sublets
A19: Fiscal cost
A20: Economic viability, IRR total project | B20: =#REF! -> #REF! | C20: 0.15 | D20: =B20/C20*10 -> #REF!
A21: Commercial viability, IRR private sector | B21: =#REF! -> #REF! | C21: 0.25 | D21: =B21/C21*10 -> #REF!
A23: Fiscal viability, public sector project NPV | B23: =#REF! -> #REF!
A24: less supply-side in-kind capture (e.g. value of public lands), NPV | B24: =-#REF! -> #REF! | C24: not yet adjusted for inflation
A25: less demand-side subsidies, NPV | B25: -2000000 | C25: tbd
A26: Balance | B26: =SUM(B23:B25) -> #REF!
A27: Fiscal viability | B27: =B26/Q!Q37 -> #REF!
E28: moving public space targets, by pop density
F29: marginal change
E30: pop density (gross) | F30: below 500 | G30: above 500 | H30: 200 | I30: 300 | J30: 400 | K30: 500 | L30: 600 | M30: 700 | N30: 800 | O30: 900 | P30: 1000
E31: open space / parks target | F31: 0.005 | G31: 0.0025 | H31: =K31+(H30-K30)/100*F31 -> 0.035 | I31: =K31+(I30-K30)/100*F31 -> 0.04 | J31: =K31+(J30-K30)/100*F31 -> 0.045 | K31: 0.05 | L31: =K31+(L30-K30)/100*G31 -> 0.0525 | M31: =K31+(M30-K30)/100*G31 -> 0.055 | N31: =K31+(N30-K30)/100*G31 -> 0.0575 | O31: =K31+(O30-K30)/100*G31 -> 0.06 | P31: =K31+(P30-K30)/100*G31 -> 0.0625
E32: amenities target | F32: 0.01 | G32: 0.005 | H32: =K32+(H30-K30)/100*F32 -> 0.07 | I32: =K32+(I30-K30)/100*F32 -> 0.08 | J32: =K32+(J30-K30)/100*F32 -> 0.09 | K32: 0.1 | L32: =K32+(L30-K30)/100*G32 -> 0.105 | M32: =K32+(M30-K30)/100*G32 -> 0.11 | N32: =K32+(N30-K30)/100*G32 -> 0.115 | O32: =K32+(O30-K30)/100*G32 -> 0.12 | P32: =K32+(P30-K30)/100*G32 -> 0.125
E33: street space target | F33: 0.015 | G33: 0.0075 | H33: =K33+(H30-K30)/100*F33 -> 0.155 | I33: =K33+(I30-K30)/100*F33 -> 0.17 | J33: =K33+(J30-K30)/100*F33 -> 0.185 | K33: 0.2 | L33: =K33+(L30-K30)/100*G33 -> 0.2075 | M33: =K33+(M30-K30)/100*G33 -> 0.215 | N33: =K33+(N30-K30)/100*G33 -> 0.2225 | O33: =K33+(O30-K30)/100*G33 -> 0.23 | P33: =K33+(P30-K30)/100*G33 -> 0.2375
E34: public space target | F34: =SUM(F31:F33) -> 0.03 | G34: =SUM(G31:G33) -> 0.015 | H34: =SUM(H31:H33) -> 0.26 | I34: =SUM(I31:I33) -> 0.29 | J34: =SUM(J31:J33) -> 0.32 | K34: =SUM(K31:K33) -> 0.35 | L34: =SUM(L31:L33) -> 0.365 | M34: =SUM(M31:M33) -> 0.38 | ... P34: =SUM(P31:P33) -> 0.425
G35: public space | H35: =H34*10000 -> 2600 | I35: =I34*10000 -> 2900 | J35: =J34*10000 -> 3200 | K35: =K34*10000 -> 3500 | L35: =L34*10000 -> 3650 | M35: =M34*10000 -> 3800 | N35: =N34*10000 -> 3950 | O35: =O34*10000 -> 4100 | P35: =P34*10000 -> 4250
G36: public space p.c. | H36: =H35/H30 -> 13 | I36: =I35/I30 -> 9.6666667 | J36: =J35/J30 -> 8 | K36: =K35/K30 -> 7 | L36: =L35/L30 -> 6.0833333 | M36: =M35/M30 -> 5.4285714 | N36: =N35/N30 -> 4.9375 | O36: =O35/O30 -> 4.5555556 | P36: =P35/P30 -> 4.25

Sheet Q_zeroed
A1: Public street network (length)
A2: Public network, by network level (in color code) | C2: 2-sided @100% | D2: 1-sided @50% | E2: zero sided (@tbd) | F2: Subtotal project-borne
B3: Arteries (main roads) | C3: 0 | D3: 0 | E3: 0 | F3: =C3+D3/2 -> 0
B4: Secondaries (distributor roads) | C4: 0 | D4: 0 | E4: 0 | F4: =C4+D4/2 -> 0
B5: Tertiaries (access and local roads) | C5: 0 | D5: 0 | E5: 0 | F5: =C5+D5/2 -> 0
B6: Subtotal project-borne | C6: =SUM(C3:C5) -> 0 | D6: =SUM(D3:D5)/2 -> 0 | E6: =SUM(E3:E5)*0 -> 0 | F6: =SUM(F3:F5) -> 0
A8: Land use (city and neighborhood scale) | X8: Lots and buildings (idealized)
A9: Land uses, by location (in color code) | C9: Environmental reservation | D9: Social reservation | E9: Other non-developable area | F9: Non-developable area | G9: Public streets | H9: City-scale public open spaces, subtotal | I9: City-scale public amenities, subtotal | J9: District-scale public open spaces, subtotal | K9: District-scale public amenities, subtotal | L9: Neighborhood-scale open spaces, subtotal | M9: Neighborhood-scale public amenities, subtotal | N9: Public lands, subtotal | O9: Private lands, subtotals | P9: Developable area, subtotals | Q9: All lands, totals | R9: Distribution (share of total) | X9: Number of lots | Y9: lot d | Z9: lot w | AA9: lot A | AB9: front margin | AC9: back margin | AD9: footprint d | AE9: side margin | AF9: side margin 2 | AG9: footprint w | AH9: footprint A | AI9: floors regular | AJ9: corner bonus | AK9: floors final | AL9: floor area | AM9: max. FAR viable | AO9: starter w | AP9: starter d | AQ9: starter f | AR9: starter w | AS9: starter d | AT9: starter f | AU9: Starter building, average floor area, if any
B10: =C9 -> Environmental reservation | C10: =C60*10000 -> 0 | F10: =SUM(C10:E10) -> 0 | Q10: =F10 -> 0 | R10: =Q10/Q37 -> #DIV/0!
B11: =D9 -> Social reservation | D11: =D60*10000 -> 0 | F11: =SUM(C11:E11) -> 0 | Q11: =F11 -> 0 | R11: =Q11/Q37 -> #DIV/0!
B12: =E9 -> Other non-developable area | E12: 0 | F12: =SUM(C12:E12) -> 0 | Q12: =F12 -> 0 | R12: =Q12/Q37 -> #DIV/0!
B13: Reservations, outside neighborhod | C13: =C10 -> 0 | D13: =D11 -> 0 | E13: =E12 -> 0 | F13: =SUM(F10:F12) -> 0 | Q13: =SUM(Q10:Q12) -> 0 | R13: =Q13/Q37 -> #DIV/0!
B14: Artery x artery (corner) | H14: 0 | I14: 0 | J14: 0 | K14: 0 | L14: 0 | M14: 0 | N14: =SUM(G14:M14) -> 0 | O14: 0 | P14: =SUM(N14:O14) -> 0 | Q14: =P14 -> 0 | R14: =Q14/Q37 -> #DIV/0! | U14: Artery x artery (corner) | X14: 0 | Y14: =Y17 -> 0 | Z14: =Y17 -> 0 | AA14: =Z14*Y14 -> 0 | AB14: =AB17 -> 0 | AC14: =AC17 -> 0 | AD14: =Y14-AB14-AC14 -> 0 | AE14: =AE17 -> 0 | AF14: =AE17 -> 0 | AG14: =Z14-AE14-AF14 -> 0 | AH14: =AG14*AD14 -> 0 | AJ14: 0 | AK14: =ROUND(AI17*(1+AJ14),0) -> 0 | AL14: =AG14*AD14*AK14 -> 0 | AM14: =IF(AA14=0,0,AL14/AA14) -> 0 | AO14: 0 | AP14: 0 | AQ14: 0 | AR14: =AO14*AG14 -> 0 | AS14: =AP14*AD14 -> 0 | AT14: =ROUND(AQ14*AK14,0) -> 0 | AU14: =AL14*AP14*AQ14 -> 0
B15: Artery x secondary (corner) | H15: 0 | I15: 0 | J15: 0 | K15: 0 | L15: 0 | M15: 0 | N15: =SUM(G15:M15) -> 0 | O15: 0 | P15: =SUM(N15:O15) -> 0 | Q15: =P15 -> 0 | R15: =Q15/Q37 -> #DIV/0! | U15: Artery x secondary (corner) | X15: 0 | Y15: =Y17 -> 0 | Z15: =Y21 -> 0 | AA15: =Z15*Y15 -> 0 | AB15: =AB17 -> 0 | AC15: =AC17 -> 0 | AD15: =Y15-AB15-AC15 -> 0 | AE15: =AE17 -> 0 | AF15: =AE21 -> 0 | AG15: =Z15-AE15-AF15 -> 0 | AH15: =AG15*AD15 -> 0 | AJ15: 0 | AK15: =ROUND(AI17*(1+AJ15),0) -> 0 | AL15: =AG15*AD15*AK15 -> 0 | AM15: =IF(AA15=0,0,AL15/AA15) -> 0 | AO15: 0 | AP15: 0 | AQ15: 0 | AR15: =AO15*AG15 -> 0 | AS15: =AP15*AD15 -> 0 | AT15: =ROUND(AQ15*AK15,0) -> 0 | AU15: =AL15*AP15*AQ15 -> 0
B16: Artery x tertiary (corner) | H16: 0 | I16: 0 | J16: 0 | K16: 0 | L16: 0 | M16: 0 | N16: =SUM(G16:M16) -> 0 | O16: 0 | P16: =SUM(N16:O16) -> 0 | Q16: =P16 -> 0 | R16: =Q16/Q37 -> #DIV/0! | U16: Artery x tertiary (corner) | X16: 0 | Y16: =Y17 -> 0 | Z16: =Y24 -> 0 | AA16: =Z16*Y16 -> 0 | AB16: =AB17 -> 0 | AC16: =AC17 -> 0 | AD16: =Y16-AB16-AC16 -> 0 | AE16: =AE17 -> 0 | AF16: =AE24 -> 0 | AG16: =Z16-AE16-AF16 -> 0 | AH16: =AG16*AD16 -> 0 | AJ16: 0 | AK16: =ROUND(AI17*(1+AJ16),0) -> 0 | AL16: =AG16*AD16*AK16 -> 0 | AM16: =IF(AA16=0,0,AL16/AA16) -> 0 | AO16: 0 | AP16: 0 | AQ16: 0 | AR16: =AO16*AG16 -> 0 | AS16: =AP16*AD16 -> 0 | AT16: =ROUND(AQ16*AK16,0) -> 0 | AU16: =AL16*AP16*AQ16 -> 0
B17: Artery (regular) | H17: 0 | I17: 0 | J17: 0 | K17: 0 | L17: 0 | M17: 0 | N17: =SUM(G17:M17) -> 0 | O17: 0 | P17: =SUM(N17:O17) -> 0 | Q17: =P17 -> 0 | R17: =Q17/Q37 -> #DIV/0! | U17: Artery (regular) | X17: 0 | Y17: 0 | Z17: 0 | AA17: =Z17*Y17 -> 0 | AB17: 0 | AC17: 0 | AD17: =Y17-AB17-AC17 -> 0 | AE17: 0 | AF17: =AE17 -> 0 | AG17: =Z17-AE17-AF17 -> 0 | AH17: =AG17*AD17 -> 0 | AI17: 0 | AJ17: 0 | AK17: =ROUND(AI17*(1+AJ17),0) -> 0 | AL17: =AG17*AD17*AK17 -> 0 | AM17: =IF(AA17=0,0,AL17/AA17) -> 0 | AO17: 0 | AP17: 0 | AQ17: 0 | AR17: =AO17*AG17 -> 0 | AS17: =AP17*AD17 -> 0 | AT17: =ROUND(AQ17*AK17,0) -> 0 | AU17: =AL17*AP17*AQ17 -> 0
A18: Land on arteries, subtotal | F18: =SUM(F14:F17) -> 0 | H18: =SUM(H14:H17) -> 0 | I18: =SUM(I14:I17) -> 0 | J18: =SUM(J14:J17) -> 0 | K18: =SUM(K14:K17) -> 0 | L18: =SUM(L14:L17) -> 0 | M18: =SUM(M14:M17) -> 0 | N18: =SUM(N14:N17) -> 0 | O18: =SUM(O14:O17) -> 0 | ... Q18: =SUM(Q14:Q17) -> 0 | R18: =Q18/Q37 -> #DIV/0! | T18: w/path | X18: =C45*2 -> 0 | Y18: =Y17 -> 0 | Z18: =Z17 -> 0 | AA18: =AA17 -> 0 | AB18: =AB17 -> 0 | AC18: =AC17 -> 0 | AD18: =AD17 -> 0 | AE18: =AE17 -> 0 | AF18: =AF17 -> 0 | ... AH18: =AH17 -> 0 | AK18: =AK17 -> 0 | AL18: =AL17 -> 0 | AM18: =IF(AA18=0,0,AL18/AA18) -> 0 | AO18: =AO17 -> 0 | AP18: =AP17 -> 0 | AQ18: =AQ17 -> 0 | AR18: =AO18*AG18 -> 0 | AS18: =AP18*AD18 -> 0 | AT18: =ROUND(AQ18*AK18,0) -> 0 | AU18: =AU17 -> 0
B19: Secondary x secondary (corner) | H19: 0 | I19: 0 | J19: 0 | K19: 0 | L19: 0 | M19: 0 | N19: =SUM(G19:M19) -> 0 | O19: 0 | P19: =SUM(N19:O19) -> 0 | Q19: =P19 -> 0 | R19: =Q19/Q37 -> #DIV/0! | U19: Secondary x secondary (corner) | X19: 0 | Y19: =Y21 -> 0 | Z19: =Y21 -> 0 | AA19: =Z19*Y19 -> 0 | AB19: =AB21 -> 0 | AC19: =AC21 -> 0 | AD19: =Y19-AB19-AC19 -> 0 | AE19: =AE21 -> 0 | AF19: =AE21 -> 0 | AG19: =Z19-AE19-AF19 -> 0 | AH19: =AG19*AD19 -> 0 | AJ19: =AJ15 -> 0 | AK19: =ROUND(AI21*(1+AJ19),0) -> 0 | AL19: =AG19*AD19*AK19 -> 0 | AM19: =IF(AA19=0,0,AL19/AA19) -> 0 | AO19: 0 | AP19: 0 | AQ19: 0 | AR19: =AO19*AG19 -> 0 | AS19: =AP19*AD19 -> 0 | AT19: =ROUND(AQ19*AK19,0) -> 0 | AU19: =AL19*AP19*AQ19 -> 0
B20: Secondary x tertiary (corner) | H20: 0 | I20: 0 | J20: 0 | K20: 0 | L20: 0 | M20: 0 | N20: =SUM(G20:M20) -> 0 | O20: 0 | P20: =SUM(N20:O20) -> 0 | Q20: =P20 -> 0 | R20: =Q20/Q37 -> #DIV/0! | U20: Secondary x tertiary (corner) | X20: 0 | Y20: =Y21 -> 0 | Z20: =Y24 -> 0 | AA20: =Z20*Y20 -> 0 | AB20: =AB21 -> 0 | AC20: =AC21 -> 0 | AD20: =Y20-AB20-AC20 -> 0 | AE20: =AE21 -> 0 | AF20: =AE24 -> 0 | AG20: =Z20-AE20-AF20 -> 0 | AH20: =AG20*AD20 -> 0 | AJ20: =AJ16 -> 0 | AK20: =ROUND(AI21*(1+AJ20),0) -> 0 | AL20: =AG20*AD20*AK20 -> 0 | AM20: =IF(AA20=0,0,AL20/AA20) -> 0 | AO20: 0 | AP20: 0 | AQ20: 0 | AR20: =AO20*AG20 -> 0 | AS20: =AP20*AD20 -> 0 | AT20: =ROUND(AQ20*AK20,0) -> 0 | AU20: =AL20*AP20*AQ20 -> 0
B21: Secondary (regular) | H21: 0 | I21: 0 | J21: 0 | K21: 0 | L21: 0 | M21: 0 | N21: =SUM(G21:M21) -> 0 | O21: 0 | P21: =SUM(N21:O21) -> 0 | Q21: =P21 -> 0 | R21: =Q21/Q37 -> #DIV/0! | U21: Secondary (regular) | X21: 0 | Y21: 0 | Z21: 0 | AA21: =Z21*Y21 -> 0 | AB21: 0 | AC21: 0 | AD21: =Y21-AB21-AC21 -> 0 | AE21: 0 | AF21: =AE21 -> 0 | AG21: =Z21-AE21-AF21 -> 0 | AH21: =AG21*AD21 -> 0 | AI21: 0 | AJ21: 0 | AK21: =ROUND(AI21*(1+AJ21),0) -> 0 | AL21: =AG21*AD21*AK21 -> 0 | AM21: =IF(AA21=0,0,AL21/AA21) -> 0 | AO21: 0 | AP21: 0 | AQ21: 0 | AR21: =AO21*AG21 -> 0 | AS21: =AP21*AD21 -> 0 | AT21: =ROUND(AQ21*AK21,0) -> 0 | AU21: =AL21*AP21*AQ21 -> 0
